Workbook

Sheet Model
B1: TCO elektrische vrachtwagens — gekalibreerd op TCO-ZET-Vracht v7.3 (Panteia / Topsector Logistiek)
B2: A. Baas Potplantenkwekerij B.V. — 2 trucks · AanZET 2026 + SPRILA
B4: Legenda: | C4: Geel/blauw = zelf invullen · zwart = formule · groen = automatisch uit blad Panteia-parameters
B6: 1. INVOER
B7: Aantal trucks | C7: 2
B8: Kilometers per truck per jaar | C8: 100000 | E8: Opgave Kwekerij Baas
B9: Ondernemingsgrootte | C9: Middelgroot | E9: Klein / Middelgroot / Groot — geldt voor de HELE groep, geconsolideerd
B10: Voertuigtype | C10: Zware trekker z/opl | E10: Kies uit blad Panteia-parameters. Stuurt verbruik, onderhoud, banden en AanZET-categorie aan
B11: Dieselverbruik — 1 op ... | C11: 3.8 | E11: Opgave Kwekerij Baas
B12: → liter per km | C12: =IF($C$11=0,0,1/$C$11)
B13: Bruto aanschafprijs e-truck | C13: 300000 | E13: Opgave Nijwa: Volvo FH Aero Electric 4x2. De 6x2 kost € 320.000
B14: Bruto aanschafprijs vergelijkbare diesel | C14: 146166 | E14: Panteia casco 'Zware trekker z/opl'. OPVRAGEN bij Nijwa — bepaalt het staatssteunplafond
B15: Netto dieselprijs per liter | C15: 1.7 | E15: Opgave Kwekerij Baas
B16: Aandeel eigen opwek (zon + accu) | C16: 1 | E16: Opgave Kwekerij Baas — volledig eigen opwek
B17: Prijs eigen opwek per kWh | C17: 0.1 | E17: Opgave Kwekerij Baas
B18: Prijs netstroom per kWh | C18: 0.21537 | E18: Panteia Parameters D6
B19: → gemengde stroomprijs | C19: =$C$16*$C$17+(1-$C$16)*$C$18
B20: Vrachtwagenheffing diesel (€/km) | C20: 0.19 | E20: Per 1 juli 2026 — zit NIET in de Panteia-tool v7.3
B21: Vrachtwagenheffing zero-emissie (€/km) | C21: 0.04 | E21: Per 1 juli 2026 — circa 80% korting
B22: Extra chauffeurskosten elektrisch per jaar | C22: 3655 | E22: Wachttijd bij laden. Panteia rekent +4,1% (E118 vs D118). Schaalt mee met de inzet
B23: Vennootschapsbelasting | C23: 0.258 | E23: Tarief 2026
B24: EIA-aftrekpercentage | C24: 0.4 | E24: EIA 2026
B25: EIA-grondslag = volledige aanschafprijs? | C25: Nee | E25: Nee = alleen de meerprijs (voorzichtig). Ja = hele aanschafprijs, zoals Panteia bij MIA doet
B26: Investering laadinfrastructuur | C26: 461500 | E26: Offerte Draccu DR283: accu 1.045 kWh + 3x DC 240 kW
B27: SPRILA-subsidie | C27: 178000 | E27: Volgens de RVO-bedragen 2026. LET OP: de Panteia-tool hanteert afwijkende SPRILA-bedragen
B29: 2. UIT HET VOERTUIGTYPE (Panteia)
B30: AanZET-categorie | C30: =INDEX('Panteia-parameters'!$J$6:$J$10,MATCH($C$10,'Panteia-parameters'!$B$6:$B$10,0))
B31: Panteia-verbruik diesel (l/km) — referentie | C31: =INDEX('Panteia-parameters'!$C$6:$C$10,MATCH($C$10,'Panteia-parameters'!$B$6:$B$10,0)) | E31: Ter vergelijking met jullie eigen 1 op-cijfer hierboven
B32: Stroomverbruik e-truck (kWh/km) | C32: =INDEX('Panteia-parameters'!$D$6:$D$10,MATCH($C$10,'Panteia-parameters'!$B$6:$B$10,0)) | E32: Inclusief laadverliezen
B33: Onderhoud diesel (€/km) | C33: =INDEX('Panteia-parameters'!$E$6:$E$10,MATCH($C$10,'Panteia-parameters'!$B$6:$B$10,0))
B34: Onderhoud elektrisch (€/km) | C34: =INDEX('Panteia-parameters'!$F$6:$F$10,MATCH($C$10,'Panteia-parameters'!$B$6:$B$10,0))
B35: Reparaties per jaar (beide) | C35: =INDEX('Panteia-parameters'!$G$6:$G$10,MATCH($C$10,'Panteia-parameters'!$B$6:$B$10,0))
B36: Banden (€/km, beide) | C36: =INDEX('Panteia-parameters'!$H$6:$H$10,MATCH($C$10,'Panteia-parameters'!$B$6:$B$10,0))
B37: Motorrijtuigenbelasting per jaar | C37: =INDEX('Panteia-parameters'!$I$6:$I$10,MATCH($C$10,'Panteia-parameters'!$B$6:$B$10,0)) | E37: Gelijk verondersteld voor diesel en elektrisch — valt vanaf 1-7-2026 terug naar het EU-minimum
B39: 3. AANZET-SUBSIDIE
B40: Subsidiepercentage | C40: =SUMIFS('Panteia-parameters'!$E$16:$E$27,'Panteia-parameters'!$C$16:$C$27,$C$30,'Panteia-parameters'!$D$16:$D$27,$C$9)
B41: Maximum per voertuig | C41: =SUMIFS('Panteia-parameters'!$F$16:$F$27,'Panteia-parameters'!$C$16:$C$27,$C$30,'Panteia-parameters'!$D$16:$D$27,$C$9)
B42: Meerprijs t.o.v. diesel | C42: =MAX(0,$C$13-$C$14)
B43: Staatssteunplafond (% van meerprijs) | C43: =INDEX('Panteia-parameters'!$D$31:$D$33,MATCH($C$9,'Panteia-parameters'!$C$31:$C$33,0))
B44: Staatssteunplafond in euro | C44: =C43*C42
...

Sheet Panteia-parameters
B1: Parameters overgenomen uit TCO-ZET-Vracht v7.3 (Panteia / Topsector Logistiek, 23-09-2024)
B2: Basisjaar 2024. Blauw = letterlijk uit de tool, met broncel erbij.
B4: VOERTUIGTYPEN
B5: Voertuigtype | C5: Diesel [l/km] | D5: Elektrisch [kWh/km] | E5: Onderhoud diesel [€/km] | F5: Onderhoud elektrisch [€/km] | G5: Reparaties [€/jaar] | H5: Banden [€/km] | I5: Wegenbelasting [€/jaar] | J5: AanZET-categorie
B6: Kleine bakwagen | C6: 0.13239976 | D6: 0.47615518 | E6: 0.057292837 | F6: 0.028646419 | G6: 551.25 | H6: 0.023121345 | I6: 380 | J6: N2
B7: Medium bakwagen | C7: 0.21063939 | D7: 0.95191942 | E7: 0.063020152 | F7: 0.031510076 | G7: 551.25 | H7: 0.022769128 | I7: 380 | J7: N3 Bakwagen (lvm <= 18t)
B8: Grote bakwagen | C8: 0.26974248 | D8: 1.3272858 | E8: 0.068747466 | F8: 0.034373733 | G8: 1102.5 | H8: 0.022416912 | I8: 380 | J8: N3 Bakwagen (lvm > 18t)
B9: Lichte trekker z/opl | C9: 0.27941148 | D9: 1.2996299 | E9: 0.080193998 | F9: 0.040096999 | G9: 1653.75 | H9: 0.03444994 | I9: 1028 | J9: N3 Trekker
B10: Zware trekker z/opl | C10: 0.34135029 | D10: 1.155 | E10: 0.09164053 | F10: 0.045820265 | G10: 1653.75 | H10: 0.046482968 | I10: 1028 | J10: N3 Trekker | K10: VERVANGEN — Volvo ERS 18-08-2026, route Ens-Naaldwijk: 1,09 kWh/km uit de accu + 6% laadverlies
B12: Bron: blad 'Invoer en categorieën', tabellen B21:K25 en B31:O35; categorie uit 'M2-Subsidie' F27:G31
B14: AANZET 2026 — PERCENTAGES EN MAXIMA
C15: AanZET-categorie | D15: Ondernemingsgrootte | E15: Max. steun [%] | F15: Max. steun [€]
C16: N2 | D16: Middelgroot | E16: 0.12 | F16: 14700
C17: N2 | D17: Klein | E17: 0.148 | F17: 18800
C18: N2 | D18: Groot | E18: 0.061 | F18: 7500
C19: N3 Bakwagen (lvm <= 18t) | D19: Middelgroot | E19: 0.2 | F19: 60500
C20: N3 Bakwagen (lvm <= 18t) | D20: Klein | E20: 0.286 | F20: 86600
C21: N3 Bakwagen (lvm <= 18t) | D21: Groot | E21: 0.103 | F21: 31100
C22: N3 Bakwagen (lvm > 18t) | D22: Middelgroot | E22: 0.21 | F22: 83200
C23: N3 Bakwagen (lvm > 18t) | D23: Klein | E23: 0.29 | F23: 115200
C24: N3 Bakwagen (lvm > 18t) | D24: Groot | E24: 0.111 | F24: 43900
C25: N3 Trekker | D25: Middelgroot | E25: 0.21 | F25: 83200
C26: N3 Trekker | D26: Klein | E26: 0.29 | F26: 115200
C27: N3 Trekker | D27: Groot | E27: 0.111 | F27: 43900
B28: Bron: blad 'M2-Subsidie' F5:I17. Komt exact overeen met de bedragen die RVO en de dealers publiceren.
B30: STAATSSTEUNPLAFOND — MAXIMALE STEUN ALS % VAN DE MEERPRIJS
C31: Groot | D31: 0.4
C32: Middelgroot | D32: 0.5
C33: Klein | D33: 0.6
B35: Bron: blad 'M2-Subsidie' F21:G23. Werkt als derde plafond naast percentage en maximumbedrag.
B37: ENERGIE- EN FINANCIELE PARAMETERS
C38: Kale dieselprijs [€/l] | D38: 1.09 | F38: Parameters D4
C39: Accijns diesel [€/l] | D39: 0.5163 | F39: Parameters D5
C40: Inkoopprijs netstroom [€/kWh] | D40: 0.21537 | F40: Parameters D6
C41: Prijs eigen opwek [€/kWh] | D41: 0.11 | F41: Parameters J47
C42: Fractie eigen opwek | D42: 0.5 | F42: Parameters J46
C43: Rente | D43: 0.039 | F43: Parameters D30
C44: Verzekering (% van bruto aanschaf) | D44: 0.035686759 | F44: Parameters D31
C45: Restwaarde na 7 jaar | D45: 0.23 | F45: Parameters I21
C46: Economische levensduur [jaar] | D46: 7 | F46: Input-Output Module D36
...

Sheet Gevoeligheid
B1: Gevoeligheidsanalyse
B2: Rekent live mee met blad Model. Alleen de eerste kolom is invoer.
B4: A. KILOMETERS PER TRUCK PER JAAR
B5: km per jaar | C5: Besparing per jaar | D5: Terugverdientijd [jaar]
B6: 60000 | C6: =(B6*((Model!$C$12*Model!$C$15+Model!$C$20+Model!$C$33)-(Model!$C$32*Model!$C$19+Model!$C$21+Model!$C$34))-Model!$C$22)*Model!$C$7+B6*Model!$C$32*Model!$C$7*Model!$C$84*(1-Model!$C$85) | D6: =IF(C6<=0,"nooit",Model!$C$56/C6)
B7: 80000 | C7: =(B7*((Model!$C$12*Model!$C$15+Model!$C$20+Model!$C$33)-(Model!$C$32*Model!$C$19+Model!$C$21+Model!$C$34))-Model!$C$22)*Model!$C$7+B7*Model!$C$32*Model!$C$7*Model!$C$84*(1-Model!$C$85) | D7: =IF(C7<=0,"nooit",Model!$C$56/C7)
B8: 100000 | C8: =(B8*((Model!$C$12*Model!$C$15+Model!$C$20+Model!$C$33)-(Model!$C$32*Model!$C$19+Model!$C$21+Model!$C$34))-Model!$C$22)*Model!$C$7+B8*Model!$C$32*Model!$C$7*Model!$C$84*(1-Model!$C$85) | D8: =IF(C8<=0,"nooit",Model!$C$56/C8)
B9: 120000 | C9: =(B9*((Model!$C$12*Model!$C$15+Model!$C$20+Model!$C$33)-(Model!$C$32*Model!$C$19+Model!$C$21+Model!$C$34))-Model!$C$22)*Model!$C$7+B9*Model!$C$32*Model!$C$7*Model!$C$84*(1-Model!$C$85) | D9: =IF(C9<=0,"nooit",Model!$C$56/C9)
B10: 150000 | C10: =(B10*((Model!$C$12*Model!$C$15+Model!$C$20+Model!$C$33)-(Model!$C$32*Model!$C$19+Model!$C$21+Model!$C$34))-Model!$C$22)*Model!$C$7+B10*Model!$C$32*Model!$C$7*Model!$C$84*(1-Model!$C$85) | D10: =IF(C10<=0,"nooit",Model!$C$56/C10)
B11: 180000 | C11: =(B11*((Model!$C$12*Model!$C$15+Model!$C$20+Model!$C$33)-(Model!$C$32*Model!$C$19+Model!$C$21+Model!$C$34))-Model!$C$22)*Model!$C$7+B11*Model!$C$32*Model!$C$7*Model!$C$84*(1-Model!$C$85) | D11: =IF(C11<=0,"nooit",Model!$C$56/C11)
B12: 200000 | C12: =(B12*((Model!$C$12*Model!$C$15+Model!$C$20+Model!$C$33)-(Model!$C$32*Model!$C$19+Model!$C$21+Model!$C$34))-Model!$C$22)*Model!$C$7+B12*Model!$C$32*Model!$C$7*Model!$C$84*(1-Model!$C$85) | D12: =IF(C12<=0,"nooit",Model!$C$56/C12)
B15: B. GEMENGDE STROOMPRIJS
B16: € per kWh | C16: Besparing per jaar | D16: Terugverdientijd [jaar]
B17: 0.11 | C17: =Model!$C$90+(Model!$C$19-B17)*Model!$C$8*Model!$C$32*Model!$C$7 | D17: =IF(C17<=0,"nooit",Model!$C$56/C17)
B18: 0.14 | C18: =Model!$C$90+(Model!$C$19-B18)*Model!$C$8*Model!$C$32*Model!$C$7 | D18: =IF(C18<=0,"nooit",Model!$C$56/C18)
B19: 0.16 | C19: =Model!$C$90+(Model!$C$19-B19)*Model!$C$8*Model!$C$32*Model!$C$7 | D19: =IF(C19<=0,"nooit",Model!$C$56/C19)
B20: 0.18 | C20: =Model!$C$90+(Model!$C$19-B20)*Model!$C$8*Model!$C$32*Model!$C$7 | D20: =IF(C20<=0,"nooit",Model!$C$56/C20)
B21: 0.2154 | C21: =Model!$C$90+(Model!$C$19-B21)*Model!$C$8*Model!$C$32*Model!$C$7 | D21: =IF(C21<=0,"nooit",Model!$C$56/C21)
B22: 0.25 | C22: =Model!$C$90+(Model!$C$19-B22)*Model!$C$8*Model!$C$32*Model!$C$7 | D22: =IF(C22<=0,"nooit",Model!$C$56/C22)
B23: 0.3 | C23: =Model!$C$90+(Model!$C$19-B23)*Model!$C$8*Model!$C$32*Model!$C$7 | D23: =IF(C23<=0,"nooit",Model!$C$56/C23)
B26: C. DIESELVERBRUIK — 1 OP ...
B27: 1 op ... | C27: Besparing per jaar | D27: Terugverdientijd [jaar]
B28: 2.9 | C28: =Model!$C$90+(1/B28-Model!$C$12)*Model!$C$8*Model!$C$15*Model!$C$7 | D28: =IF(C28<=0,"nooit",Model!$C$56/C28)
B29: 3.2 | C29: =Model!$C$90+(1/B29-Model!$C$12)*Model!$C$8*Model!$C$15*Model!$C$7 | D29: =IF(C29<=0,"nooit",Model!$C$56/C29)
B30: 3.5 | C30: =Model!$C$90+(1/B30-Model!$C$12)*Model!$C$8*Model!$C$15*Model!$C$7 | D30: =IF(C30<=0,"nooit",Model!$C$56/C30)
B31: 3.8 | C31: =Model!$C$90+(1/B31-Model!$C$12)*Model!$C$8*Model!$C$15*Model!$C$7 | D31: =IF(C31<=0,"nooit",Model!$C$56/C31)
B32: 4.1 | C32: =Model!$C$90+(1/B32-Model!$C$12)*Model!$C$8*Model!$C$15*Model!$C$7 | D32: =IF(C32<=0,"nooit",Model!$C$56/C32)
B33: 4.5 | C33: =Model!$C$90+(1/B33-Model!$C$12)*Model!$C$8*Model!$C$15*Model!$C$7 | D33: =IF(C33<=0,"nooit",Model!$C$56/C33)
B34: 5 | C34: =Model!$C$90+(1/B34-Model!$C$12)*Model!$C$8*Model!$C$15*Model!$C$7 | D34: =IF(C34<=0,"nooit",Model!$C$56/C34)
B37: D. ONDERNEMINGSGROOTTE
B38: Grootte | C38: AanZET totaal | D38: Extra investering | E38: Terugverdientijd [jaar]
B39: Klein | C39: =MIN(Model!$C$13*SUMIFS('Panteia-parameters'!$E$16:$E$27,'Panteia-parameters'!$C$16:$C$27,Model!$C$30,'Panteia-parameters'!$D$16:$D$27,B39),SUMIFS('Panteia-parameters'!$F$16:$F$27,'Panteia-parameters'!$C$16:$C$27,Model!$C$30,'Panteia-parameters'!$D$16:$D$27,B39),INDEX('Panteia-parameters'!$D$31:$D$33,MATCH(B39,'Panteia-parameters'!$C$31:$C$33,0))*Model!$C$42)*Model!$C$7 | D39: =(Model!$C$42-MIN(Model!$C$13*SUMIFS('Panteia-parameters'!$E$16:$E$27,'Panteia-parameters'!$C$16:$C$27,Model!$C$30,'Panteia-parameters'!$D$16:$D$27,B39),SUMIFS('Panteia-parameters'!$F$16:$F$27,'Panteia-parameters'!$C$16:$C$27,Model!$C$30,'Panteia-parameters'!$D$16:$D$27,B39),INDEX('Panteia-parameters'!$D$31:$D$33,MATCH(B39,'Panteia-parameters'!$C$31:$C$33,0))*Model!$C$42)-MAX(0,IF(Model!$C$25="Ja",Model!$C$13,Model!$C$42)-MIN(Model!$C$13*SUMIFS('Panteia-parameters'!$E$16:$E$27,'Panteia-parameters'!$C$16:$C$27,Model!$C$30,'Panteia-parameters'!$D$16:$D$27,B39),SUMIFS('Panteia-parameters'!$F$16:$F$27,'Panteia-parameters'!$C$16:$C$27,Model!$C$30,'Panteia-parameters'!$D$16:$D$27,B39),INDEX('Panteia-parameters'!$D$31:$D$33,MATCH(B39,'Panteia-parameters'!$C$31:$C$33,0))*Model!$C$42))*Model!$C$24*Model!$C$23)*Model!$C$7+Model!$C$55 | E39: =IF(Model!$C$90<=0,"nooit",D39/Model!$C$90)
B40: Middelgroot | C40: =MIN(Model!$C$13*SUMIFS('Panteia-parameters'!$E$16:$E$27,'Panteia-parameters'!$C$16:$C$27,Model!$C$30,'Panteia-parameters'!$D$16:$D$27,B40),SUMIFS('Panteia-parameters'!$F$16:$F$27,'Panteia-parameters'!$C$16:$C$27,Model!$C$30,'Panteia-parameters'!$D$16:$D$27,B40),INDEX('Panteia-parameters'!$D$31:$D$33,MATCH(B40,'Panteia-parameters'!$C$31:$C$33,0))*Model!$C$42)*Model!$C$7 | D40: =(Model!$C$42-MIN(Model!$C$13*SUMIFS('Panteia-parameters'!$E$16:$E$27,'Panteia-parameters'!$C$16:$C$27,Model!$C$30,'Panteia-parameters'!$D$16:$D$27,B40),SUMIFS('Panteia-parameters'!$F$16:$F$27,'Panteia-parameters'!$C$16:$C$27,Model!$C$30,'Panteia-parameters'!$D$16:$D$27,B40),INDEX('Panteia-parameters'!$D$31:$D$33,MATCH(B40,'Panteia-parameters'!$C$31:$C$33,0))*Model!$C$42)-MAX(0,IF(Model!$C$25="Ja",Model!$C$13,Model!$C$42)-MIN(Model!$C$13*SUMIFS('Panteia-parameters'!$E$16:$E$27,'Panteia-parameters'!$C$16:$C$27,Model!$C$30,'Panteia-parameters'!$D$16:$D$27,B40),SUMIFS('Panteia-parameters'!$F$16:$F$27,'Panteia-parameters'!$C$16:$C$27,Model!$C$30,'Panteia-parameters'!$D$16:$D$27,B40),INDEX('Panteia-parameters'!$D$31:$D$33,MATCH(B40,'Panteia-parameters'!$C$31:$C$33,0))*Model!$C$42))*Model!$C$24*Model!$C$23)*Model!$C$7+Model!$C$55 | E40: =IF(Model!$C$90<=0,"nooit",D40/Model!$C$90)
B41: Groot | C41: =MIN(Model!$C$13*SUMIFS('Panteia-parameters'!$E$16:$E$27,'Panteia-parameters'!$C$16:$C$27,Model!$C$30,'Panteia-parameters'!$D$16:$D$27,B41),SUMIFS('Panteia-parameters'!$F$16:$F$27,'Panteia-parameters'!$C$16:$C$27,Model!$C$30,'Panteia-parameters'!$D$16:$D$27,B41),INDEX('Panteia-parameters'!$D$31:$D$33,MATCH(B41,'Panteia-parameters'!$C$31:$C$33,0))*Model!$C$42)*Model!$C$7 | D41: =(Model!$C$42-MIN(Model!$C$13*SUMIFS('Panteia-parameters'!$E$16:$E$27,'Panteia-parameters'!$C$16:$C$27,Model!$C$30,'Panteia-parameters'!$D$16:$D$27,B41),SUMIFS('Panteia-parameters'!$F$16:$F$27,'Panteia-parameters'!$C$16:$C$27,Model!$C$30,'Panteia-parameters'!$D$16:$D$27,B41),INDEX('Panteia-parameters'!$D$31:$D$33,MATCH(B41,'Panteia-parameters'!$C$31:$C$33,0))*Model!$C$42)-MAX(0,IF(Model!$C$25="Ja",Model!$C$13,Model!$C$42)-MIN(Model!$C$13*SUMIFS('Panteia-parameters'!$E$16:$E$27,'Panteia-parameters'!$C$16:$C$27,Model!$C$30,'Panteia-parameters'!$D$16:$D$27,B41),SUMIFS('Panteia-parameters'!$F$16:$F$27,'Panteia-parameters'!$C$16:$C$27,Model!$C$30,'Panteia-parameters'!$D$16:$D$27,B41),INDEX('Panteia-parameters'!$D$31:$D$33,MATCH(B41,'Panteia-parameters'!$C$31:$C$33,0))*Model!$C$42))*Model!$C$24*Model!$C$23)*Model!$C$7+Model!$C$55 | E41: =IF(Model!$C$90<=0,"nooit",D41/Model!$C$90)
